# -*- coding: utf-8 -*-
#  Â©  2016 ACSONE SA/NV (<http://acsone.eu>)
# License AGPL-3.0 or later (http://www.gnu.org/licenses/agpl.html).
import odoo.tests.common as common
from odoo.exceptions import ValidationError


class TestL10nBePartnerIdentificationID(common.TransactionCase):

    def test_validate_id_card(self):
        partner_id_category = self.env.ref(
            'l10n_be_partner_identification_id.'
            'l10n_be_id_card_category')
        partner_1 = self.env.ref('base.res_partner_1')
        # born before 2000
        partner_1.write({'id_numbers':  [(0, 0,  {
            'name': '000-0000000-97',
            'category_id': partner_id_category.id
        })]})
        id_number = partner_1.id_numbers[0]
        self.assertEqual(id_number.name, '000-0000000-97')
        # born after 2000
        id_number.write({'name': '000-0000001-01',
                         'category_id': partner_id_category.id})
        self.assertEqual(id_number.name, '000-0000001-01')
        with self.assertRaises(ValidationError), self.env.cr.savepoint():
            # check invalid id number
            id_number.name = '000-0000001-02'
